[2024-11-02T04:41:25.189+0000] {local_task_job_runner.py:123} INFO - ::group::Pre task execution logs
[2024-11-02T04:41:25.619+0000] {taskinstance.py:2612} INFO - Dependencies all met for dep_context=non-requeueable deps ti=<TaskInstance: Airflow_proyecto.extract_deaths scheduled__2024-10-28T00:00:00+00:00 [queued]>
[2024-11-02T04:41:25.795+0000] {taskinstance.py:2612} INFO - Dependencies all met for dep_context=requeueable deps ti=<TaskInstance: Airflow_proyecto.extract_deaths scheduled__2024-10-28T00:00:00+00:00 [queued]>
[2024-11-02T04:41:25.819+0000] {taskinstance.py:2865} INFO - Starting attempt 1 of 1
[2024-11-02T04:41:26.099+0000] {taskinstance.py:2888} INFO - Executing <Task(PythonOperator): extract_deaths> on 2024-10-28 00:00:00+00:00
[2024-11-02T04:41:26.214+0000] {standard_task_runner.py:72} INFO - Started process 469 to run task
[2024-11-02T04:41:26.207+0000] {standard_task_runner.py:104} INFO - Running: ['***', 'tasks', 'run', 'Airflow_proyecto', 'extract_deaths', 'scheduled__2024-10-28T00:00:00+00:00', '--job-id', '97', '--raw', '--subdir', 'DAGS_FOLDER/dags.py', '--cfg-path', '/tmp/tmp4vzmqi0c']
[2024-11-02T04:41:26.275+0000] {standard_task_runner.py:105} INFO - Job 97: Subtask extract_deaths
[2024-11-02T04:41:29.043+0000] {task_command.py:467} INFO - Running <TaskInstance: Airflow_proyecto.extract_deaths scheduled__2024-10-28T00:00:00+00:00 [running]> on host a1cf71838f37
[2024-11-02T04:41:29.878+0000] {taskinstance.py:3131} INFO - Exporting env vars: AIRFLOW_CTX_DAG_EMAIL='***@example.com' AIRFLOW_CTX_DAG_OWNER='Airflow_proyecto' AIRFLOW_CTX_DAG_ID='Airflow_proyecto' AIRFLOW_CTX_TASK_ID='extract_deaths' AIRFLOW_CTX_EXECUTION_DATE='2024-10-28T00:00:00+00:00' AIRFLOW_CTX_TRY_NUMBER='1' AIRFLOW_CTX_DAG_RUN_ID='scheduled__2024-10-28T00:00:00+00:00'
[2024-11-02T04:41:29.916+0000] {taskinstance.py:731} INFO - ::endgroup::
[2024-11-02T04:41:30.101+0000] {logging_mixin.py:190} INFO - Conected successfully to database ***!
[2024-11-02T04:41:30.122+0000] {etl.py:180} INFO - Starting data extraction
[2024-11-02T04:41:30.600+0000] {taskinstance.py:3310} ERROR - Task failed with exception
Traceback (most recent call last):
  File "/home/airflow/.local/lib/python3.10/site-packages/sqlalchemy/engine/base.py", line 1910, in _execute_context
    self.dialect.do_execute(
  File "/home/airflow/.local/lib/python3.10/site-packages/sqlalchemy/engine/default.py", line 736, in do_execute
    cursor.execute(statement, parameters)
psycopg2.errors.UndefinedTable: relation "CauseOfDeaths" does not exist
LINE 2: FROM "CauseOfDeaths" AS "CauseOfDeaths_1"
             ^


The above exception was the direct cause of the following exception:

Traceback (most recent call last):
  File "/home/airflow/.local/lib/python3.10/site-packages/airflow/models/taskinstance.py", line 767, in _execute_task
    result = _execute_callable(context=context, **execute_callable_kwargs)
  File "/home/airflow/.local/lib/python3.10/site-packages/airflow/models/taskinstance.py", line 733, in _execute_callable
    return ExecutionCallableRunner(
  File "/home/airflow/.local/lib/python3.10/site-packages/airflow/utils/operator_helpers.py", line 252, in run
    return self.func(*args, **kwargs)
  File "/home/airflow/.local/lib/python3.10/site-packages/airflow/models/baseoperator.py", line 406, in wrapper
    return func(self, *args, **kwargs)
  File "/home/airflow/.local/lib/python3.10/site-packages/airflow/operators/python.py", line 238, in execute
    return_value = self.execute_callable()
  File "/home/airflow/.local/lib/python3.10/site-packages/airflow/operators/python.py", line 256, in execute_callable
    return runner.run(*self.op_args, **self.op_kwargs)
  File "/home/airflow/.local/lib/python3.10/site-packages/airflow/utils/operator_helpers.py", line 252, in run
    return self.func(*args, **kwargs)
  File "/opt/airflow/dags/etl.py", line 183, in extract_data_deaths
    df = pd.read_sql(query, con=engine)
  File "/home/airflow/.local/lib/python3.10/site-packages/pandas/io/sql.py", line 682, in read_sql
    return pandas_sql.read_query(
  File "/home/airflow/.local/lib/python3.10/site-packages/pandas/io/sql.py", line 1776, in read_query
    result = self.execute(sql, params)
  File "/home/airflow/.local/lib/python3.10/site-packages/pandas/io/sql.py", line 1599, in execute
    return self.con.exec_driver_sql(sql, *args)
  File "/home/airflow/.local/lib/python3.10/site-packages/sqlalchemy/engine/base.py", line 1770, in exec_driver_sql
    return self._exec_driver_sql(
  File "/home/airflow/.local/lib/python3.10/site-packages/sqlalchemy/engine/base.py", line 1674, in _exec_driver_sql
    ret = self._execute_context(
  File "/home/airflow/.local/lib/python3.10/site-packages/sqlalchemy/engine/base.py", line 1953, in _execute_context
    self._handle_dbapi_exception(
  File "/home/airflow/.local/lib/python3.10/site-packages/sqlalchemy/engine/base.py", line 2134, in _handle_dbapi_exception
    util.raise_(
  File "/home/airflow/.local/lib/python3.10/site-packages/sqlalchemy/util/compat.py", line 211, in raise_
    raise exception
  File "/home/airflow/.local/lib/python3.10/site-packages/sqlalchemy/engine/base.py", line 1910, in _execute_context
    self.dialect.do_execute(
  File "/home/airflow/.local/lib/python3.10/site-packages/sqlalchemy/engine/default.py", line 736, in do_execute
    cursor.execute(statement, parameters)
sqlalchemy.exc.ProgrammingError: (psycopg2.errors.UndefinedTable) relation "CauseOfDeaths" does not exist
LINE 2: FROM "CauseOfDeaths" AS "CauseOfDeaths_1"
             ^

[SQL: SELECT "CauseOfDeaths_1".id, "CauseOfDeaths_1"."Country", "CauseOfDeaths_1"."Code", "CauseOfDeaths_1"."Year", "CauseOfDeaths_1"."Cardiovascular", "CauseOfDeaths_1"."TotalDeaths" 
FROM "CauseOfDeaths" AS "CauseOfDeaths_1"]
(Background on this error at: https://sqlalche.me/e/14/f405)
[2024-11-02T04:41:30.872+0000] {taskinstance.py:1225} INFO - Marking task as FAILED. dag_id=Airflow_proyecto, task_id=extract_deaths, run_id=scheduled__2024-10-28T00:00:00+00:00, execution_date=20241028T000000, start_date=20241102T044125, end_date=20241102T044130
[2024-11-02T04:41:31.161+0000] {taskinstance.py:340} INFO - ::group::Post task execution logs
[2024-11-02T04:41:31.175+0000] {standard_task_runner.py:124} ERROR - Failed to execute job 97 for task extract_deaths ((psycopg2.errors.UndefinedTable) relation "CauseOfDeaths" does not exist
LINE 2: FROM "CauseOfDeaths" AS "CauseOfDeaths_1"
             ^

[SQL: SELECT "CauseOfDeaths_1".id, "CauseOfDeaths_1"."Country", "CauseOfDeaths_1"."Code", "CauseOfDeaths_1"."Year", "CauseOfDeaths_1"."Cardiovascular", "CauseOfDeaths_1"."TotalDeaths" 
FROM "CauseOfDeaths" AS "CauseOfDeaths_1"]
(Background on this error at: https://sqlalche.me/e/14/f405); 469)
Traceback (most recent call last):
  File "/home/airflow/.local/lib/python3.10/site-packages/sqlalchemy/engine/base.py", line 1910, in _execute_context
    self.dialect.do_execute(
  File "/home/airflow/.local/lib/python3.10/site-packages/sqlalchemy/engine/default.py", line 736, in do_execute
    cursor.execute(statement, parameters)
psycopg2.errors.UndefinedTable: relation "CauseOfDeaths" does not exist
LINE 2: FROM "CauseOfDeaths" AS "CauseOfDeaths_1"
             ^


The above exception was the direct cause of the following exception:

Traceback (most recent call last):
  File "/home/airflow/.local/lib/python3.10/site-packages/airflow/task/task_runner/standard_task_runner.py", line 117, in _start_by_fork
    ret = args.func(args, dag=self.dag)
  File "/home/airflow/.local/lib/python3.10/site-packages/airflow/cli/cli_config.py", line 49, in command
    return func(*args, **kwargs)
  File "/home/airflow/.local/lib/python3.10/site-packages/airflow/utils/cli.py", line 115, in wrapper
    return f(*args, **kwargs)
  File "/home/airflow/.local/lib/python3.10/site-packages/airflow/cli/commands/task_command.py", line 483, in task_run
    task_return_code = _run_task_by_selected_method(args, _dag, ti)
  File "/home/airflow/.local/lib/python3.10/site-packages/airflow/cli/commands/task_command.py", line 256, in _run_task_by_selected_method
    return _run_raw_task(args, ti)
  File "/home/airflow/.local/lib/python3.10/site-packages/airflow/cli/commands/task_command.py", line 341, in _run_raw_task
    return ti._run_raw_task(
  File "/home/airflow/.local/lib/python3.10/site-packages/airflow/utils/session.py", line 97, in wrapper
    return func(*args, session=session, **kwargs)
  File "/home/airflow/.local/lib/python3.10/site-packages/airflow/models/taskinstance.py", line 3004, in _run_raw_task
    return _run_raw_task(
  File "/home/airflow/.local/lib/python3.10/site-packages/airflow/models/taskinstance.py", line 273, in _run_raw_task
    TaskInstance._execute_task_with_callbacks(
  File "/home/airflow/.local/lib/python3.10/site-packages/airflow/models/taskinstance.py", line 3158, in _execute_task_with_callbacks
    result = self._execute_task(context, task_orig)
  File "/home/airflow/.local/lib/python3.10/site-packages/airflow/models/taskinstance.py", line 3182, in _execute_task
    return _execute_task(self, context, task_orig)
  File "/home/airflow/.local/lib/python3.10/site-packages/airflow/models/taskinstance.py", line 767, in _execute_task
    result = _execute_callable(context=context, **execute_callable_kwargs)
  File "/home/airflow/.local/lib/python3.10/site-packages/airflow/models/taskinstance.py", line 733, in _execute_callable
    return ExecutionCallableRunner(
  File "/home/airflow/.local/lib/python3.10/site-packages/airflow/utils/operator_helpers.py", line 252, in run
    return self.func(*args, **kwargs)
  File "/home/airflow/.local/lib/python3.10/site-packages/airflow/models/baseoperator.py", line 406, in wrapper
    return func(self, *args, **kwargs)
  File "/home/airflow/.local/lib/python3.10/site-packages/airflow/operators/python.py", line 238, in execute
    return_value = self.execute_callable()
  File "/home/airflow/.local/lib/python3.10/site-packages/airflow/operators/python.py", line 256, in execute_callable
    return runner.run(*self.op_args, **self.op_kwargs)
  File "/home/airflow/.local/lib/python3.10/site-packages/airflow/utils/operator_helpers.py", line 252, in run
    return self.func(*args, **kwargs)
  File "/opt/airflow/dags/etl.py", line 183, in extract_data_deaths
    df = pd.read_sql(query, con=engine)
  File "/home/airflow/.local/lib/python3.10/site-packages/pandas/io/sql.py", line 682, in read_sql
    return pandas_sql.read_query(
  File "/home/airflow/.local/lib/python3.10/site-packages/pandas/io/sql.py", line 1776, in read_query
    result = self.execute(sql, params)
  File "/home/airflow/.local/lib/python3.10/site-packages/pandas/io/sql.py", line 1599, in execute
    return self.con.exec_driver_sql(sql, *args)
  File "/home/airflow/.local/lib/python3.10/site-packages/sqlalchemy/engine/base.py", line 1770, in exec_driver_sql
    return self._exec_driver_sql(
  File "/home/airflow/.local/lib/python3.10/site-packages/sqlalchemy/engine/base.py", line 1674, in _exec_driver_sql
    ret = self._execute_context(
  File "/home/airflow/.local/lib/python3.10/site-packages/sqlalchemy/engine/base.py", line 1953, in _execute_context
    self._handle_dbapi_exception(
  File "/home/airflow/.local/lib/python3.10/site-packages/sqlalchemy/engine/base.py", line 2134, in _handle_dbapi_exception
    util.raise_(
  File "/home/airflow/.local/lib/python3.10/site-packages/sqlalchemy/util/compat.py", line 211, in raise_
    raise exception
  File "/home/airflow/.local/lib/python3.10/site-packages/sqlalchemy/engine/base.py", line 1910, in _execute_context
    self.dialect.do_execute(
  File "/home/airflow/.local/lib/python3.10/site-packages/sqlalchemy/engine/default.py", line 736, in do_execute
    cursor.execute(statement, parameters)
sqlalchemy.exc.ProgrammingError: (psycopg2.errors.UndefinedTable) relation "CauseOfDeaths" does not exist
LINE 2: FROM "CauseOfDeaths" AS "CauseOfDeaths_1"
             ^

[SQL: SELECT "CauseOfDeaths_1".id, "CauseOfDeaths_1"."Country", "CauseOfDeaths_1"."Code", "CauseOfDeaths_1"."Year", "CauseOfDeaths_1"."Cardiovascular", "CauseOfDeaths_1"."TotalDeaths" 
FROM "CauseOfDeaths" AS "CauseOfDeaths_1"]
(Background on this error at: https://sqlalche.me/e/14/f405)
[2024-11-02T04:41:31.618+0000] {local_task_job_runner.py:266} INFO - Task exited with return code 1
[2024-11-02T04:41:31.724+0000] {local_task_job_runner.py:245} INFO - ::endgroup::
